<?xml version="1.0" ?>
<robot name="two-wheeled-robot" xmlns:xacro="http://www.ros.org/wiki/xacro">

<xacro:include filename="$(find two-wheeled-robot_description)/urdf/materials.xacro" />
<xacro:include filename="$(find two-wheeled-robot_description)/urdf/two-wheeled-robot.trans" />
<xacro:include filename="$(find two-wheeled-robot_description)/urdf/two-wheeled-robot.gazebo" />
<link name="base_link">
  <inertial>
    <origin xyz="8.166246229178452e-15 0.0 0.049756872488880555" rpy="0 0 0"/>
    <mass value="2.1344303822554895"/>
    <inertia ixx="0.007528" iyy="0.007599" izz="0.014205" ixy="0.0" iyz="-0.0" ixz="0.0"/>
  </inertial>
  <visual>
    <origin xyz="0 0 0" rpy="0 0 0"/>
    <geometry>
      <mesh filename="package://two-wheeled-robot_description/meshes/base_link.stl" scale="0.001 0.001 0.001"/>
    </geometry>
    <material name="silver"/>
  </visual>
  <collision>
    <origin xyz="0 0 0" rpy="0 0 0"/>
    <geometry>
      <mesh filename="package://two-wheeled-robot_description/meshes/base_link.stl" scale="0.001 0.001 0.001"/>
    </geometry>
  </collision>
</link>

<link name="right_wheel_1">
  <inertial>
    <origin xyz="-5.790023100122029e-18 -0.012499999999999997 0.0" rpy="0 0 0"/>
    <mass value="0.1826050729899067"/>
    <inertia ixx="0.000124" iyy="0.000228" izz="0.000124" ixy="-0.0" iyz="0.0" ixz="0.0"/>
  </inertial>
  <visual>
    <origin xyz="-0.0 0.1 -0.05" rpy="0 0 0"/>
    <geometry>
      <mesh filename="package://two-wheeled-robot_description/meshes/right_wheel_1.stl" scale="0.001 0.001 0.001"/>
    </geometry>
    <material name="silver"/>
  </visual>
  <collision>
    <origin xyz="-0.0 0.1 -0.05" rpy="0 0 0"/>
    <geometry>
      <mesh filename="package://two-wheeled-robot_description/meshes/right_wheel_1.stl" scale="0.001 0.001 0.001"/>
    </geometry>
  </collision>
</link>

<link name="left_wheel_1">
  <inertial>
    <origin xyz="-5.790023100122029e-18 0.012499999999999997 0.0" rpy="0 0 0"/>
    <mass value="0.1826050729899067"/>
    <inertia ixx="0.000124" iyy="0.000228" izz="0.000124" ixy="0.0" iyz="-0.0" ixz="0.0"/>
  </inertial>
  <visual>
    <origin xyz="-0.0 -0.1 -0.05" rpy="0 0 0"/>
    <geometry>
      <mesh filename="package://two-wheeled-robot_description/meshes/left_wheel_1.stl" scale="0.001 0.001 0.001"/>
    </geometry>
    <material name="silver"/>
  </visual>
  <collision>
    <origin xyz="-0.0 -0.1 -0.05" rpy="0 0 0"/>
    <geometry>
      <mesh filename="package://two-wheeled-robot_description/meshes/left_wheel_1.stl" scale="0.001 0.001 0.001"/>
    </geometry>
  </collision>
</link>

<joint name="Rev1" type="continuous">
  <origin xyz="0.0 -0.1 0.05" rpy="0 0 0"/>
  <parent link="base_link"/>
  <child link="right_wheel_1"/>
  <axis xyz="0.0 1.0 0.0"/>
  <!-- <dynamics damping="0.0" friction="0.5"/> -->
</joint>

<joint name="Rev2" type="continuous">
  <origin xyz="0.0 0.1 0.05" rpy="0 0 0"/>
  <parent link="base_link"/>
  <child link="left_wheel_1"/>
  <axis xyz="0.0 1.0 0.0"/>
  <!-- <dynamics damping="0.0" friction="0.5"/> -->
</joint>

</robot>
